Workbook
Name _xlchart.v1.0: #REF!
Name _xlchart.v1.1: 'Copia di Tour List'!$BA$5:$BA$45
Name _xlchart.v1.1: #REF!
Name _xlchart.v1.0: 'Copia di Tour List'!$BA$3

Sheet Pricing
A1: NCC Pricing Calculator - v.1.9 | N1: Release date | O1: 46041
A2: SERVICE DETAILS | B2: Personalizza dati | C2: Dati utilizzati | D2: Dati Default
A3: Destinazione | B3: Chianti Classico - TOUR FD
A4: Tipo | B4: TOUR FD | C4: =IF(B4="- - - - -",D4,B4) -> TOUR FD | D4: =VLOOKUP(B3,'Tour List'!A2:K52,3,0) -> TOUR FD
A5: Kilometraggio | C5: =IF(B5="",D5,B5) -> 250 | D5: =VLOOKUP(B3,'Tour List'!A2:K43,5,0) -> 250
A6: Extra Km se non si parte/arriva da Siena | C6: =B6
A7: Durata del servizio (ore) | C7: =IF(B7="",D7,B7) -> 8 | D7: =VLOOKUP(B3,'Tour List'!A2:K43,4,0) -> 8
A8: Estensione del servizio, con cliente (ore) | C8: =IF(B8="",D8,B8)
A9: Ore di spostamento se non si parte/arriva da Siena | C9: =IF(B9="",D9,B9)
A10: Toll € | C10: =IF(B10="",D10,B10) -> 0 | D10: =VLOOKUP(B3,'Tour List'!A2:K43,6,0) -> 0
A11: Pax (relativo solo alle esperienze) | B11: 2 | C11: =B11 -> 2
A12: Esperienze (p.p.) solo se presenti | C12: =IF(B12="",D12,B12) -> 70 | D12: =VLOOKUP(B3,'Tour List'!A2:K43,11,0) -> 70
A13: PRICING POLICIES
A14: Stagionalità | B14: Low | C14: =B14 -> Low
A15: Riempimento | B15: Car (2pax) | C15: =B15 -> Car (2pax)
A16: VAT | B16: 0.1 | C16: =B16 -> 0.1
A17: Card Fees | B17: 0.05 | C17: =B17 -> 0.05
A18: Maggiorazioni (notturno, festivo) | B18: 0 | C18: =B18 -> 0
A19: Costi trasferta € | B19: 0 | C19: =B19 -> 0
A21: PRICE
A22: Taxable transport | B22: {=INDEX('Pricing Calculator'!E2:H6,MATCH(B14,'Pricing Calculator'!E2:E6,0),MATCH(B15,'Pricing Calculator'!E3:H3,0))} -> 433.9574
A23: Taxable experience | B23: {=INDEX('Pricing Calculator'!E10:H14,MATCH(B14,'Pricing Calculator'!E10:E14,0),MATCH(B15,'Pricing Calculator'!E10:H10,0))} -> 147
A24: Maggiorazione | B24: =(B22+B23)*B18 -> 0
A25: Costi trasferta € | B25: =B19 -> 0
A26: Taxable Price | B26: =B22+B23+B24+B25 -> 580.9574 | C26: =CEILING(B26,5) -> 585
A27: =CONCATENATE("VAT (",(B16*100),"%)") -> VAT (10%) | B27: =B26*B16 -> 58.09574 | C27: =CEILING(D27,5) -> 645 | D27: =C26+B27 -> 643.09574
A28: =CONCATENATE("CC fees (",(B17*100),"%)") -> CC fees (5%) | B28: =(B26+B27)*B17 -> 31.952657
A29: FINAL PRICE | B29: =B26+B27+B28 -> 671.00579 | C29: =CEILING(B29,5) -> 675

Sheet Preventivi
A1: USER | B1: DATE | C1: CLIENTE | D1: URL | E1: DESTINAZIONE | F1: TIPO | G1: MILEAGE | H1: EXTRA_KM | I1: DURATA | J1: EXTRA DURATA | K1: PEDAGGIO | L1: PAX (ESPERIENZE) | M1: EXP PER PAX | N1: STAGIONE | O1: RIEMPIMENTO | P1: VAT % | Q1: CARD FEES % | R1: MAGGIORAZIONI | S1: TRASFERTA | T1: IMPONIBILE | U1: VAT € | V1: CC FEES € | W1: PREZZO FINALE | X1: PREZZO CLIENTE | Y1: % SCONTO | Z1: SCONTP € | AA1: DEPOSITO % | AB1: DEPOSITO IMPONIBILE | AC1: DEPOSITO FULL | AD1: SALDO IMPONIBILE | AE1: SALDO BANCA | AF1: SALDO CC
A2: michelamenegon@gmail.com | B2: 27 December 2025 | C2: Ying Goh | D2: https://docs.google.com/document/d/1Ux04QH-POEJAv-hxb3j95oA3h9n8WKv9MJtxXn0ebtE/edit?usp=drivesdk | F2: TOUR FD+ | G2: 750 | H2: 75 | I2: 11 | J2: 1 | K2: 30 | M2: 0 | N2: Average | O2: Van (3-6 pax) | P2: 0.1 | Q2: 0.05 | R2: 0 | S2: 0 | T2: 1050 | U2: 104.9649 | V2: 57.730693 | W2: 1215 | X2: 1155 | Y2: 0.1 | Z2: 1050 | AA2: 0.3 | AB2: 315 | AC2: 365 | AD2: 735 | AE2: 810 | AF2: 850
A3: michelamenegon@gmail.com | B3: 27 December 2025 | C3: Ying Goh | D3: https://docs.google.com/document/d/1q0FuAuMEE6HYeVTbUiYiI4EQedN6oX7q8zDc-pcnlT8/edit?usp=drivesdk | F3: TOUR FD+ | G3: 750 | H3: 75 | I3: 11 | J3: 1 | K3: 30 | M3: 0 | N3: Average | O3: Van (3-6 pax) | P3: 0.1 | Q3: 0.05 | R3: 0 | S3: 0 | T3: 1050 | U3: 104.9649 | V3: 57.730693 | W3: 1215 | X3: 1155 | Y3: 0.1 | Z3: 1050 | AA3: 0.3 | AB3: 315 | AC3: 365 | AD3: 735 | AE3: 810 | AF3: 850
A4: michelamenegon@gmail.com | B4: 28 December 2025 | C4: Cliente Argiano 29/12/25 | D4: https://docs.google.com/document/d/1RGpvI1GW4-sqj5h_f1y2EwakEbhIjrpGtCmL9zMiFPs/edit?usp=drivesdk | F4: TOUR FD+ | G4: 350 | H4: 250 | I4: 12 | J4: 4 | K4: 20 | M4: 0 | N4: Low | O4: Full (7-8 pax) | P4: 0.1 | Q4: 0.05 | R4: 0 | S4: 0 | T4: 1005 | U4: 100.1002 | V4: 55.055108 | W4: 1160 | X4: 1110 | Y4: 0 | Z4: 1110 | AA4: 0.3 | AB4: 335 | AC4: 390 | AD4: 810 | AE4: 890 | AF4: 935
A5: michelamenegon@gmail.com | B5: 28 December 2025 | C5: Julia Guest | D5: https://docs.google.com/document/d/1iA16qTkmkjjvfHaj-o93aGIx5qJlH1VgVYsW8cSI1VE/edit?usp=drivesdk | F5: TRF | G5: 500 | H5: 90 | I5: 6 | J5: 1 | K5: 27 | M5: 0 | N5: High | O5: Car (2pax) | P5: 0.1 | Q5: 0.05 | R5: 0 | S5: 0 | T5: 615 | U5: 61.172754 | V5: 33.645015 | W5: 710 | X5: 680 | Y5: 0.1 | Z5: 620 | AA5: 0.3 | AB5: 190 | AC5: 220 | AD5: 440 | AE5: 480 | AF5: 505
A6: michelamenegon@gmail.com | B6: 28 December 2025 | C6: Ying Goh | D6: https://docs.google.com/document/d/1S4-slFR-Ebpu_LRa3sWrLp3NJ-mvyQY8VY6tioiOJvc/edit?usp=drivesdk | F6: TOUR FD | G6: 250 | H6: 140 | I6: 10 | J6: 3 | K6: 0 | M6: 0 | N6: Average | O6: Van (3-6 pax) | P6: 0.1 | Q6: 0.05 | R6: 0 | S6: 0 | T6: 740 | U6: 73.834785 | V6: 40.609132 | W6: 855 | X6: 815 | Y6: 0.1 | Z6: 745 | AA6: 0.3 | AB6: 225 | AC6: 260 | AD6: 525 | AE6: 580 | AF6: 605
A7: michelamenegon@gmail.com | B7: 29 December 2025 | C7: Tina Benton | D7: https://docs.google.com/document/d/1CkTZU-UbISqKAYc0hACPHnbE8KHroVRAOa6x2v5dHNA/edit?usp=drivesdk | F7: TOUR FD | G7: 250 | H7: 80 | I7: 8 | J7: 2 | K7: 0 | M7: 0 | N7: High | O7: Van (3-6 pax) | P7: 0.1 | Q7: 0.05 | R7: 0 | S7: 0 | T7: 685 | U7: 68.15959 | V7: 37.487774 | W7: 790 | X7: 755 | Y7: 0.1 | Z7: 690 | AA7: 0.3 | AB7: 210 | AC7: 245 | AD7: 485 | AE7: 535 | AF7: 560
A8: michelamenegon@gmail.com | B8: 29 December 2025 | C8: Vilena Tjurina | D8: https://docs.google.com/document/d/1sx7zVJ8b58Jf3-o24PjRwoyKm2_RuWOYEthAJ19jkpM/edit?usp=drivesdk | F8: TOUR FD | G8: 250 | H8: 60 | I8: 8 | J8: 1 | K8: 0 | M8: 0 | N8: Low | O8: Van (3-6 pax) | P8: 0.1 | Q8: 0.05 | R8: 0 | S8: 0 | T8: 545 | U8: 54.366754 | V8: 29.901715 | W8: 630 | X8: 600 | Z8: 600 | AA8: 0.3 | AB8: 180 | AC8: 210 | AD8: 440 | AE8: 485 | AF8: 505
A9: michelamenegon@gmail.com | B9: 29 December 2025 | C9: Vilena Tjurina | D9: https://docs.google.com/document/d/1jUDIKng0eiTwTryp9EK9pQMEcxi-WjA0Azj1wP94rYc/edit?usp=drivesdk | F9: TOUR FD | G9: 250 | H9: 60 | I9: 8 | J9: 1 | K9: 0 | M9: 0 | N9: Low | O9: Van (3-6 pax) | P9: 0.1 | Q9: 0.05 | R9: 0 | S9: 0 | T9: 545 | U9: 54.366754 | V9: 29.901715 | W9: 630 | X9: 600 | Z9: 600 | AA9: 0.3 | AB9: 180 | AC9: 210 | AD9: 440 | AE9: 485 | AF9: 505
A10: michelamenegon@gmail.com | B10: 30 December 2025 | C10: Cliente Athena ?? | D10: https://docs.google.com/document/d/1Cn7x0-NlgoSpyQjgedYwgLnUWJjfGBJ0HoSy4us4D9g/edit?usp=drivesdk | F10: TRF | G10: 150 | I10: 3 | K10: 0 | M10: 0 | N10: High | O10: Van (3-6 pax) | P10: 0.1 | Q10: 0.05 | R10: 0 | S10: 0 | T10: 235 | U10: 23.099859 | V10: 12.704922 | W10: 270 | X10: 260 | Y10: 0.1 | Z10: 240 | AA10: 0.3 | AB10: 75 | AC10: 90 | AD10: 170 | AE10: 190 | AF10: 200
A11: michelamenegon@gmail.com | B11: 30 December 2025 | C11: Vilena Tjurina | D11: https://docs.google.com/document/d/1HgrHJl9zE0qWfFUcOOBGptsSO4wrGgiNNDvjuoWCx2o/edit?usp=drivesdk | F11: TOUR HD | G11: 150 | H11: 60 | I11: 5 | J11: 1 | K11: 0 | M11: 0 | N11: Low | O11: Van (3-6 pax) | P11: 0.1 | Q11: 0.05 | R11: 0 | S11: 0 | T11: 370 | U11: 36.806196 | V11: 20.243408 | W11: 430 | X11: 260 | Z11: 260 | AA11: 0.3 | AB11: 80 | AC11: 95 | AD11: 150 | AE11: 165 | AF11: 175
A12: michelamenegon@gmail.com | B12: 30 December 2025 | C12: Vilena Tjurina | D12: https://docs.google.com/document/d/1eXSLJ3db5H-qixd9hc5aDCnzI0JlbPoy-FoB3KvdvMU/edit?usp=drivesdk | F12: TOUR FD | G12: 200 | H12: 60 | I12: 7 | J12: 1 | K12: 0 | M12: 0 | N12: Low | O12: Van (3-6 pax) | P12: 0.1 | Q12: 0.05 | R12: 0 | S12: 0 | T12: 475 | U12: 47.190712 | V12: 25.954891 | W12: 550 | X12: 260 | Z12: 260 | AA12: 0.3 | AB12: 80 | AC12: 95 | AD12: 120 | AE12: 130 | AF12: 140
A13: michelamenegon@gmail.com | B13: 30 December 2025 | C13: Vilena Tjurina | D13: https://docs.google.com/document/d/1Hn_4YKUIkEaY-YafIbHU_biHQbv0eSJWhlORRoxGooY/edit?usp=drivesdk | F13: TOUR FD | G13: 200 | H13: 60 | I13: 7 | J13: 1 | K13: 0 | M13: 0 | N13: Low | O13: Van (3-6 pax) | P13: 0.1 | Q13: 0.05 | R13: 0 | S13: 0 | T13: 475 | U13: 47.190712 | V13: 25.954891 | W13: 550 | X13: 525 | Z13: 525 | AA13: 0.3 | AB13: 160 | AC13: 185 | AD13: 385 | AE13: 425 | AF13: 445
A14: michelamenegon@gmail.com | B14: 31 December 2025 | C14: Wilson Brazil | D14: https://docs.google.com/document/d/16uqc7Up-sLiT7DGiFcMnRMhDxau1EmvQz0QkYS2JplA/edit?usp=drivesdk | F14: TOUR FD+ | G14: 300 | I14: 11 | K14: 0 | M14: 0 | N14: Average | O14: Car (2pax) | P14: 0.1 | Q14: 0.05 | R14: 0 | S14: 0 | T14: 605 | U14: 60.101324 | V14: 33.055728 | W14: 695 | X14: 670 | Y14: 0.1 | Z14: 610 | AA14: 0.3 | AB14: 185 | AC14: 215 | AD14: 430 | AE14: 475 | AF14: 495
A15: michelamenegon@gmail.com | B15: 31 December 2025 | C15: Jim Winkler | D15: https://docs.google.com/document/d/1HMxBE_xi-Geic86RU16VXYxrloaITg9s-608ogf9Y3w/edit?usp=drivesdk | F15: TOUR FD+ | G15: 300 | H15: 200 | I15: 11 | J15: 3 | K15: 0 | M15: 0 | N15: High | O15: Full (7-8 pax) | P15: 0.1 | Q15: 0.05 | R15: 0 | S15: 0 | T15: 1040 | U15: 103.97366 | V15: 57.185514 | W15: 1205 | X15: 1145 | Y15: 0.1 | Z15: 1045 | AA15: 0.3 | AB15: 315 | AC15: 365 | AD15: 735 | AE15: 810 | AF15: 850
A16: michelamenegon@gmail.com | B16: 31 December 2025 | C16: Jim Winkler | D16: https://docs.google.com/document/d/1Gyx934oyxLFXdKuvmYdJVU5ry97wrg3zzT0cAZX5rAU/edit?usp=drivesdk | F16: TOUR FD+ | G16: 250 | H16: 200 | I16: 10 | J16: 3 | K16: 0 | M16: 0 | N16: High | O16: Full (7-8 pax) | P16: 0.1 | Q16: 0.05 | R16: 0 | S16: 0 | T16: 935 | U16: 93.134679 | V16: 51.224074 | W16: 1080 | X16: 1030 | Y16: 0.1 | Z16: 940 | AA16: 0.3 | AB16: 285 | AC16: 330 | AD16: 660 | AE16: 730 | AF16: 765
A17: michelamenegon@gmail.com | B17: 31 December 2025 | C17: Jim Winkler | D17: https://docs.google.com/document/d/1Wm4A-vWybeMF4hygFBmUIk559UXNbh99IkovkgeBVio/edit?usp=drivesdk | F17: TOUR FD+ | G17: 250 | H17: 200 | I17: 10 | J17: 3 | K17: 0 | M17: 0 | N17: High | O17: Full (7-8 pax) | P17: 0.1 | Q17: 0.05 | R17: 0 | S17: 0 | T17: 935 | U17: 93.134679 | V17: 51.224074 | W17: 1080 | X17: 1030 | Y17: 0.1 | Z17: 940 | AA17: 0.3 | AB17: 285 | AC17: 330 | AD17: 660 | AE17: 730 | AF17: 765
A18: michelamenegon@gmail.com | B18: 31 December 2025 | C18: Jim Winkler | D18: https://docs.google.com/document/d/1ShEetJKAlcUUl0XYJPbLclbf2ulJnbbcuui48gRY9K4/edit?usp=drivesdk | F18: TOUR FD | G18: 250 | H18: 200 | I18: 8 | J18: 3 | K18: 0 | M18: 0 | N18: High | O18: Full (7-8 pax) | P18: 0.1 | Q18: 0.05 | R18: 0 | S18: 0 | T18: 830 | U18: 82.62515 | V18: 45.443832 | W18: 955 | X18: 915 | Y18: 0.1 | Z18: 835 | AA18: 0.3 | AB18: 255 | AC18: 295 | AD18: 590 | AE18: 645 | AF18: 680
A19: michelamenegon@gmail.com | B19: 01 January 2026 | C19: Amy Dickey | D19: https://docs.google.com/document/d/1SeafGxO8lhnhCKgd-VQUNqBFpU5jiWr8vcpysSNGr8k/edit?usp=drivesdk | F19: TOUR FD | G19: 250 | I19: 9 | K19: 0 | M19: 0 | N19: High | O19: Van (3-6 pax) | P19: 0.1 | Q19: 0.05 | R19: 0 | S19: 0 | T19: 640 | U19: 63.879092 | V19: 35.1335 | W19: 740 | X19: 705 | Y19: 0.1 | Z19: 645 | AA19: 0.3 | AB19: 195 | AC19: 230 | AD19: 455 | AE19: 500 | AF19: 525
A20: michelamenegon@gmail.com | B20: 01 January 2026 | C20: Emily Moroney | D20: https://docs.google.com/document/d/1qnIHWQ_SS9aQNWDm_g3Ii82qwYP9QZB6-aktSQ0I8xY/edit?usp=drivesdk | F20: TRF | G20: 500 | H20: 20 | I20: 6 | J20: 1 | K20: 27 | M20: 0 | N20: High | O20: Car (2pax) | P20: 0.1 | Q20: 0.05 | R20: 0 | S20: 0 | T20: 590 | U20: 58.917851 | V20: 32.404818 | W20: 685 | X20: 650 | Y20: 0.1 | Z20: 595 | AA20: 0.3 | AB20: 180 | AC20: 210 | AD20: 420 | AE20: 460 | AF20: 485
A21: michelamenegon@gmail.com | B21: 01 January 2026 | C21: Emily Moroney | D21: https://docs.google.com/document/d/1k5oAhsbxVq38MKIeGX6jiSZ3LFEgM7qZ1oRZM60xKiA/edit?usp=drivesdk | F21: TOUR FD+ | G21: 750 | H21: 75 | I21: 13 | J21: 1 | K21: 27 | M21: 0 | N21: Average | O21: Van (3-6 pax) | P21: 0.1 | Q21: 0.05 | R21: 0 | S21: 0 | T21: 1115 | U21: 111.28146 | V21: 61.204803 | W21: 1290 | X21: 1230 | Y21: 0.1 | Z21: 1120 | AA21: 0.3 | AB21: 340 | AC21: 395 | AD21: 790 | AE21: 865 | AF21: 910
A22: michelamenegon@gmail.com | B22: 04 January 2026 | C22: Claudine | D22: https://docs.google.com/document/d/1gH-oAndu6X0uN_DZeB6r1NO4Xs3Zd6PalM8FOX_812A/edit?usp=drivesdk | F22: TRF | G22: 500 | I22: 6 | K22: 30 | M22: 0 | N22: High | O22: Van (3-6 pax) | P22: 0.1 | Q22: 0.05 | R22: 0 | S22: 0 | T22: 650 | U22: 64.646749 | V22: 35.555712 | W22: 750 | X22: 715 | Y22: 0.1 | Z22: 650 | AA22: 0.3 | AB22: 195 | AC22: 230 | AD22: 455 | AE22: 505 | AF22: 530
A23: michelamenegon@gmail.com | B23: 04 January 2026 | C23: Client Athena | D23: https://docs.google.com/document/d/1qvr4JFJ-CSc8BBvUiqp5MXmzEUelnT15Yb8B_48n61w/edit?usp=drivesdk | F23: TRF | G23: 160 | I23: 4 | K23: 0 | M23: 0 | N23: Low | O23: Car (2pax) | P23: 0.1 | Q23: 0.05 | R23: 0 | S23: 0 | T23: 190 | U23: 18.938991 | V23: 10.416445 | W23: 220 | X23: 210 | Z23: 210 | AA23: 0.3 | AB23: 65 | AC23: 80 | AD23: 155 | AE23: 170 | AF23: 180
A24: michelamenegon@gmail.com | B24: 05 January 2026 | C24: Suzanne Conley | D24: https://docs.google.com/document/d/14An-KTWCesFnSvy8YElBGjuLFKkJl4FDgVTx3UkfwiA/edit?usp=drivesdk | F24: TOUR FD | G24: 550 | H24: 40 | I24: 11 | J24: 1 | K24: 30 | M24: 0 | N24: High | O24: Full (7-8 pax) | P24: 0.1 | Q24: 0.05 | R24: 0 | S24: 0 | T24: 1345 | U24: 134.03412 | V24: 73.718767 | W24: 1550 | X24: 1480 | Y24: 0.1 | Z24: 1350 | AA24: 0.3 | AB24: 405 | AC24: 470 | AD24: 950 | AE24: 1045 | AF24: 1095
A25: michelamenegon@gmail.com | B25: 05 January 2026 | C25: Suzanne Conley | D25: https://docs.google.com/document/d/1_flYYrbNfpWai_cBOmH2nZ5rg1aEJ4GKhtZq61rFDo0/edit?usp=drivesdk | F25: TRF | G25: 830 | H25: 20 | I25: 9 | J25: 1 | K25: 60 | M25: 0 | N25: High | O25: Full (7-8 pax) | P25: 0.1 | Q25: 0.05 | R25: 0 | S25: 0 | T25: 1020 | U25: 101.92901 | V25: 56.060956 | W25: 1180 | X25: 1125 | Y25: 0.1 | Z25: 1025 | AA25: 0.3 | AB25: 310 | AC25: 360 | AD25: 720 | AE25: 795 | AF25: 835
A26: michelamenegon@gmail.com | B26: 05 January 2026 | C26: Suzanne Conley | D26: https://docs.google.com/document/d/1xaW990GKjFWzSD-9DSGFNTPW_Y9blT79T5jRMHCrXA0/edit?usp=drivesdk | F26: TOUR FD | G26: 600 | H26: 40 | I26: 11 | J26: 1 | K26: 30 | M26: 0 | N26: High | O26: Full (7-8 pax) | P26: 0.1 | Q26: 0.05 | R26: 0 | S26: 0 | T26: 1400 | U26: 139.87891 | V26: 76.933401 | W26: 1620 | X26: 1540 | Y26: 0.1 | Z26: 1400 | AA26: 0.3 | AB26: 420 | AC26: 490 | AD26: 980 | AE26: 1080 | AF26: 1135
A27: michelamenegon@gmail.com | B27: 05 January 2026 | C27: Karen Harmatuk | D27: https://docs.google.com/document/d/1UPVb9WINU5G34QXps8GGig28G21izizL0jmBRrKIrs0/edit?usp=drivesdk | F27: TOUR FD | G27: 250 | I27: 9 | K27: 0 | M27: 0 | N27: Average | O27: Car (2pax) | P27: 0.1 | Q27: 0.05 | R27: 0 | S27: 0 | T27: 500 | U27: 49.672543 | V27: 27.319899 | W27: 575 | X27: 550 | Y27: 0.1 | Z27: 500 | AA27: 0.3 | AB27: 150 | AC27: 175 | AD27: 350 | AE27: 385 | AF27: 405
A28: michelamenegon@gmail.com | B28: 05 January 2026 | C28: Scott Swanstrom | D28: https://docs.google.com/document/d/1Ukn6E4sUDQXBfJvkc0xNsjG1RYL_d5HhCMyGRVEUBaM/edit?usp=drivesdk | F28: TRF | G28: 500 | H28: 85 | I28: 8 | J28: 2 | K28: 0 | M28: 0 | N28: High | O28: Car (2pax) | P28: 0.1 | Q28: 0.05 | R28: 0 | S28: 0 | T28: 660 | U28: 65.579502 | V28: 36.068726 | W28: 760 | X28: 730 | Y28: 0.1 | Z28: 665 | AA28: 0.3 | AB28: 200 | AC28: 235 | AD28: 470 | AE28: 515 | AF28: 540
A29: michelamenegon@gmail.com | B29: 07 January 2026 | C29: Mel Roth | D29: https://docs.google.com/document/d/1122aPVTVzY0ga9gR2zpvvxjl5y4qahQcTJ5Xxo7zg6c/edit?usp=drivesdk | F29: TRF | G29: 415 | I29: 6 | K29: 15 | M29: 0 | N29: High | O29: Car (2pax) | P29: 0.1 | Q29: 0.05 | R29: 0 | S29: 0 | T29: 475 | U29: 47.302523 | V29: 26.016388 | W29: 550 | X29: 525 | Y29: 0.1 | Z29: 480 | AA29: 0.3 | AB29: 145 | AC29: 170 | AD29: 340 | AE29: 375 | AF29: 390
A30: michelamenegon@gmail.com | B30: 07 January 2026 | C30: Mel Roth | D30: https://docs.google.com/document/d/1ttEQOFsn8UC1PCASpUcK19AXoh4mmqk2I4BNnNg-gTc/edit?usp=drivesdk | F30: TRF | G30: 250 | I30: 3 | K30: 10 | M30: 0 | N30: High | O30: Car (2pax) | P30: 0.1 | Q30: 0.05 | R30: 0 | S30: 0 | T30: 270 | U30: 26.925082 | V30: 14.808795 | W30: 315 | X30: 300 | Y30: 0.1 | Z30: 275 | AA30: 0.3 | AB30: 85 | AC30: 100 | AD30: 195 | AE30: 215 | AF30: 225
A31: michelamenegon@gmail.com | B31: 07 January 2026 | C31: Stacy | D31: https://docs.google.com/document/d/1yld9tQ1_kNjybvw0V-5RwO8R15bRYrgTEAMR30Ixg1Y/edit?usp=drivesdk | F31: TOUR FD+ | G31: 550 | I31: 2 | K31: 50 | M31: 0 | N31: Low | O31: Car (2pax) | P31: 0.1 | Q31: 0.05 | R31: 0 | S31: 0 | T31: 505 | U31: 50.048771 | V31: 27.526824 | W31: 580 | X31: 560 | Y31: 0.1 | Z31: 510 | AA31: 0.3 | AB31: 155 | AC31: 180 | AD31: 360 | AE31: 395 | AF31: 415
A32: michelamenegon@gmail.com | B32: 07 January 2026 | C32: Panayiota Costari | D32: https://docs.google.com/document/d/12-OelmxSQssdwS-JprYE42fS5HhC_nC0sSbfg2zP8qA/edit?usp=drivesdk | F32: TOUR FD+ | G32: 300 | H32: 140 | I32: 10 | J32: 2 | K32: 0 | M32: 0 | N32: Average | O32: Full (7-8 pax) | P32: 0.1 | Q32: 0.05 | R32: 0 | S32: 0 | T32: 900 | U32: 89.588695 | V32: 49.273782 | W32: 1035 | X32: 990 | Y32: 0.1 | Z32: 900 | AA32: 0.3 | AB32: 270 | AC32: 315 | AD32: 630 | AE32: 695 | AF32: 730
A33: michelamenegon@gmail.com | B33: 07 January 2026 | C33: Torre del Fuggisole | D33: https://docs.google.com/document/d/1lAEPMBilU4jfRCwAP2xiMsxg9FLMwcR4LMjKAgBN08g/edit?usp=drivesdk | F33: TOUR HD | G33: 100 | I33: 4 | K33: 0 | M33: 0 | N33: Low | O33: Van (3-6 pax) | P33: 0.1 | Q33: 0.05 | R33: 0 | S33: 0 | T33: 255 | U33: 25.043764 | V33: 13.77407 | W33: 290 | X33: 285 | Y33: 0.1 | Z33: 260 | AA33: 0.3 | AB33: 80 | AC33: 95 | AD33: 185 | AE33: 205 | AF33: 215
A34: michelamenegon@gmail.com | B34: 08 January 2026 | C34: Signori Baladi | D34: https://docs.google.com/document/d/1kgxMne3qdXaf3tNSJQol3f60s1YaG5Q9YaVJGTnUGSc/edit?usp=drivesdk | F34: TRF | G34: 150 | I34: 3 | K34: 0 | M34: 0 | N34: Average | O34: Car (2pax) | P34: 0.1 | Q34: 0.05 | R34: 0 | S34: 0 | T34: 180 | U34: 17.962509 | V34: 9.8793798 | W34: 210 | X34: 200 | Y34: 0.1 | Z34: 185 | AA34: 0.3 | AB34: 60 | AC34: 70 | AD34: 135 | AE34: 145 | AF34: 155
A35: michelamenegon@gmail.com | B35: 08 January 2026 | C35: Ying Goh | D35: https://docs.google.com/document/d/1dfxSz1zxGuxg-kwqiRW8BC-g8FOB6bq1zivZhdngk0w/edit?usp=drivesdk | F35: TOUR FD+ | G35: 750 | H35: 75 | I35: 16 | J35: 2 | K35: 30 | M35: 0 | N35: Low | O35: Van (3-6 pax) | P35: 0.1 | Q35: 0.05 | R35: 0 | S35: 0 | T35: 1120 | U35: 111.68068 | V35: 61.424376 | W35: 1290 | X35: 1230 | Y35: 0.1 | Z35: 1120 | AA35: 0.3 | AB35: 340 | AC35: 395 | AD35: 785 | AE35: 865 | AF35: 910
A36: michelamenegon@gmail.com | B36: 09 January 2026 | C36: DEBORAH KOPS | D36: https://docs.google.com/document/d/1yqDqXyyuFZrs9o04o8eiZx6VeP8Cl5Codmd9iZFXkxQ/edit?usp=drivesdk | F36: TOUR HD | G36: 150 | I36: 5 | K36: 0 | M36: 0 | N36: High | O36: Car (2pax) | P36: 0.1 | Q36: 0.05 | R36: 0 | S36: 0 | T36: 325 | U36: 32.270683 | V36: 17.748876 | W36: 375 | X36: 360 | Y36: 0.1 | Z36: 330 | AA36: 0.3 | AB36: 100 | AC36: 120 | AD36: 235 | AE36: 260 | AF36: 270
A37: michelamenegon@gmail.com | B37: 09 January 2026 | C37: DEBORAH KOPS | D37: https://docs.google.com/document/d/1NIka7xw960RETGMUexilfELq2FC-m9qdE9aLyRhP2pE/edit?usp=drivesdk | F37: TOUR FD | G37: 250 | I37: 9 | K37: 0 | M37: 0 | N37: High | O37: Car (2pax) | P37: 0.1 | Q37: 0.05 | R37: 0 | S37: 0 | T37: 545 | U37: 54.297228 | V37: 29.863475 | W37: 630 | X37: 600 | Y37: 0.1 | Z37: 550 | AA37: 0.3 | AB37: 165 | AC37: 195 | AD37: 390 | AE37: 430 | AF37: 450
A38: michelamenegon@gmail.com | B38: 09 January 2026 | C38: Teresa Pusley | D38: https://docs.google.com/document/d/1WJIayU3LusH_ZBZiHYZYtiqmY4cXSQfOyrzGkV0h9B4/edit?usp=drivesdk | F38: TOUR FD+ | G38: 250 | H38: 140 | I38: 9 | J38: 2 | K38: 0 | M38: 0 | N38: Average | O38: Van (3-6 pax) | P38: 0.1 | Q38: 0.05 | R38: 0 | S38: 0 | T38: 680 | U38: 67.97036 | V38: 37.383698 | W38: 790 | X38: 750 | Y38: 0.1 | Z38: 685 | AA38: 0.3 | AB38: 210 | AC38: 245 | AD38: 485 | AE38: 530 | AF38: 560
A39: michelamenegon@gmail.com | B39: 09 January 2026 | C39: Teresa Pusley | D39: https://docs.google.com/document/d/17ZvQxpUKur0v2uA-01cIHg5J1jMpLI_3rnf-msNtP48/edit?usp=drivesdk | F39: TOUR FD+ | G39: 250 | H39: 140 | I39: 10 | J39: 2 | K39: 0 | M39: 0 | N39: Average | O39: Van (3-6 pax) | P39: 0.1 | Q39: 0.05 | R39: 0 | S39: 0 | T39: 720 | U39: 71.976358 | V39: 39.586997 | W39: 835 | X39: 795 | Y39: 0.1 | Z39: 725 | AA39: 0.3 | AB39: 220 | AC39: 255 | AD39: 510 | AE39: 560 | AF39: 590
A40: michelamenegon@gmail.com | B40: 09 January 2026 | C40: Teresa Pusley | D40: https://docs.google.com/document/d/1JyKm2xJDFSObNr2NnV8OIEm9RFCdYnvdKyv1eTZxQLw/edit?usp=drivesdk | F40: TOUR FD+ | G40: 300 | H40: 140 | I40: 10 | J40: 2 | K40: 0 | M40: 0 | N40: Average | O40: Van (3-6 pax) | P40: 0.1 | Q40: 0.05 | R40: 0 | S40: 0 | T40: 765 | U40: 76.245925 | V40: 41.935259 | W40: 885 | X40: 845 | Y40: 0.1 | Z40: 770 | AA40: 0.3 | AB40: 235 | AC40: 275 | AD40: 545 | AE40: 595 | AF40: 625
...

Sheet Pricing Calculator
A2: COST BREAKDOWN | C2: RECTIFIED | E2: SERVIZIO
A3: Fuel Cost | B3: =(Pricing!C5)*'Base Operating Costs'!$B$13 -> 47.5 | F3: Car (2pax) | G3: Van (3-6 pax) | H3: Full (7-8 pax)
A4: Depreciation | B4: =(Pricing!C5)*'Base Operating Costs'!B14 -> 35.179303 | E4: Low | F4: =('Pricing Calculator'!$C$9*(1+'Pricing Policies'!$C5/100)*'Pricing Policies'!D$4*IF(Pricing!$C$4="TRF",1,(1+Markups!$B$4/100)))+('Pricing Calculator'!$C$14*(1+Markups!$B$5/100)+'Pricing Calculator'!$B$11) -> 433.9574 | G4: =('Pricing Calculator'!$C$9*(1+'Pricing Policies'!$C5/100)*'Pricing Policies'!E$4*IF(Pricing!$C$4="TRF",1,(1+Markups!$B$4/100)))+('Pricing Calculator'!$C$14*(1+Markups!$B$5/100)+'Pricing Calculator'!$B$11) -> 510.53812 | H4: =('Pricing Calculator'!$C$9*(1+'Pricing Policies'!$C5/100)*'Pricing Policies'!F$4*IF(Pricing!$C$4="TRF",1,(1+Markups!$B$4/100)))+('Pricing Calculator'!$C$14*(1+Markups!$B$5/100)+'Pricing Calculator'!$B$11) -> 612.64574
A5: Costi fissi | B5: ='Base Operating Costs'!B15*(Pricing!C5) -> 40.250469 | E5: Average | F5: =('Pricing Calculator'!$C$9*(1+'Pricing Policies'!$C6/100)*'Pricing Policies'!D$4*IF(Pricing!$C$4="TRF",1,(1+Markups!$B$4/100)))+('Pricing Calculator'!$C$14*(1+Markups!$B$5/100)+'Pricing Calculator'!$B$11) -> 462.67517 | G5: =('Pricing Calculator'!$C$9*(1+'Pricing Policies'!$C6/100)*'Pricing Policies'!E$4*IF(Pricing!$C$4="TRF",1,(1+Markups!$B$4/100)))+('Pricing Calculator'!$C$14*(1+Markups!$B$5/100)+'Pricing Calculator'!$B$11) -> 544.32373 | H5: =('Pricing Calculator'!$C$9*(1+'Pricing Policies'!$C6/100)*'Pricing Policies'!F$4*IF(Pricing!$C$4="TRF",1,(1+Markups!$B$4/100)))+('Pricing Calculator'!$C$14*(1+Markups!$B$5/100)+'Pricing Calculator'!$B$11) -> 653.18847
A6: Driver Cost | B6: =Pricing!C7*'Base Operating Costs'!$B$4 -> 176 | E6: High | F6: =('Pricing Calculator'!$C$9*(1+'Pricing Policies'!$C7/100)*'Pricing Policies'!D$4*IF(Pricing!$C$4="TRF",1,(1+Markups!$B$4/100)))+('Pricing Calculator'!$C$14*(1+Markups!$B$5/100)+'Pricing Calculator'!$B$11) -> 505.75182 | G6: =('Pricing Calculator'!$C$9*(1+'Pricing Policies'!$C7/100)*'Pricing Policies'!E$4*IF(Pricing!$C$4="TRF",1,(1+Markups!$B$4/100)))+('Pricing Calculator'!$C$14*(1+Markups!$B$5/100)+'Pricing Calculator'!$B$11) -> 595.00214 | H6: =('Pricing Calculator'!$C$9*(1+'Pricing Policies'!$C7/100)*'Pricing Policies'!F$4*IF(Pricing!$C$4="TRF",1,(1+Markups!$B$4/100)))+('Pricing Calculator'!$C$14*(1+Markups!$B$5/100)+'Pricing Calculator'!$B$11) -> 714.00257
A7: Tolls | B7: =Pricing!C10 -> 0
A8: Service Extension | B8: 0
A9: Total Cost Transport | B9: =B3+B4+B5+B6+B7 -> 298.92977 | C9: =B9*((100+'Pricing Policies'!$I$4*EXP(-1*Pricing!$C$5/'Pricing Policies'!$I$5))/100)*IF(Pricing!$C$5<'Pricing Policies'!$I$7,1,(100-('Pricing Policies'!$I$6/100*Pricing!$C$5)+('Pricing Policies'!$I$7*'Pricing Policies'!$I$6/100))/100) -> 300.31654 | E9: ESPERIENZE | K9: 66
A10: Service extention hour cost | B10: {=Pricing!C8*(INDEX('Pricing Policies'!A17:F22,MATCH(Pricing!B14,'Pricing Policies'!A17:A22,0),MATCH(Pricing!B15,'Pricing Policies'!A17:F17,0)))} -> 0 | F10: Car (2pax) | G10: Van (3-6 pax) | H10: Full (7-8 pax) | K10: 77
A11: Total Extention | B11: =B10 -> 0 | E11: Low | F11: ='Pricing Calculator'!$B$16*(1+'Pricing Policies'!$C12/100)*'Pricing Policies'!D$11 -> 147 | G11: ='Pricing Calculator'!$B$16*(1+'Pricing Policies'!$C12/100)*'Pricing Policies'!E$11 -> 161.7 | H11: ='Pricing Calculator'!$B$16*(1+'Pricing Policies'!$C12/100)*'Pricing Policies'!F$11 -> 176.4 | K11: 88
A12: Only Driver add.km cost | B12: =(Pricing!C6)*'Base Operating Costs'!$B$16 -> 0 | C12: =B12*((100+'Pricing Policies'!$I$9*EXP(-1*Pricing!$C$6/'Pricing Policies'!$I$10))/100)*IF(Pricing!$C$6<'Pricing Policies'!$I$12,1,(100-('Pricing Policies'!$I$11/100*Pricing!$C$6)+('Pricing Policies'!$I$12*'Pricing Policies'!$I$11/100))/100) -> 0 | E12: Average | F12: ='Pricing Calculator'!$B$16*(1+'Pricing Policies'!$C13/100)*'Pricing Policies'!D$11 -> 154 | G12: ='Pricing Calculator'!$B$16*(1+'Pricing Policies'!$C13/100)*'Pricing Policies'!E$11 -> 169.4 | H12: ='Pricing Calculator'!$B$16*(1+'Pricing Policies'!$C13/100)*'Pricing Policies'!F$11 -> 184.8
A13: Only Driver add. hour cost | B13: {=Pricing!C9*(INDEX('Pricing Policies'!A17:F22,MATCH("Vuoto",'Pricing Policies'!A17:A22,0),MATCH(Pricing!B15,'Pricing Policies'!A17:F17,0)))} -> 0 | E13: High | F13: ='Pricing Calculator'!$B$16*(1+'Pricing Policies'!$C14/100)*'Pricing Policies'!D$11 -> 163.8 | G13: ='Pricing Calculator'!$B$16*(1+'Pricing Policies'!$C14/100)*'Pricing Policies'!E$11 -> 180.18 | H13: ='Pricing Calculator'!$B$16*(1+'Pricing Policies'!$C14/100)*'Pricing Policies'!F$11 -> 196.56
A14: Total Only Driver Cost | B14: =B12+B13 -> 0 | C14: =MAX(B13,C12) -> 0
A15: Experiences | B15: =Pricing!C12*Pricing!C11 -> 140
A16: Total Cost Experiences | B16: =B15 -> 140 | E16: ESTENSIONE DI SERVIZIO O TRASFERIMENTO
F17: Car (2pax) | G17: Van (3-6 pax) | H17: Full (7-8 pax)
E18: Vuoto | F18: ='Base Operating Costs'!$B$5*'Pricing Policies'!D$18*'Pricing Policies'!$B19 -> 49.203 | G18: ='Base Operating Costs'!$B$5*'Pricing Policies'!E$18*'Pricing Policies'!$B19 -> 54.67 | H18: ='Base Operating Costs'!$B$5*'Pricing Policies'!F$18*'Pricing Policies'!$B19 -> 60.137
E19: Low | F19: ='Base Operating Costs'!$B$5*'Pricing Policies'!D$18*'Pricing Policies'!$B20 -> 58.905 | G19: ='Base Operating Costs'!$B$5*'Pricing Policies'!E$18*'Pricing Policies'!$B20 -> 65.45 | H19: ='Base Operating Costs'!$B$5*'Pricing Policies'!F$18*'Pricing Policies'!$B20 -> 71.995
E20: Average | F20: ='Base Operating Costs'!$B$5*'Pricing Policies'!D$18*'Pricing Policies'!$B21 -> 69.3 | G20: ='Base Operating Costs'!$B$5*'Pricing Policies'!E$18*'Pricing Policies'!$B21 -> 77 | H20: ='Base Operating Costs'!$B$5*'Pricing Policies'!F$18*'Pricing Policies'!$B21 -> 84.7
E21: High | F21: ='Base Operating Costs'!$B$5*'Pricing Policies'!D$18*'Pricing Policies'!$B22 -> 79.695 | G21: ='Base Operating Costs'!$B$5*'Pricing Policies'!E$18*'Pricing Policies'!$B22 -> 88.55 | H21: ='Base Operating Costs'!$B$5*'Pricing Policies'!F$18*'Pricing Policies'!$B22 -> 97.405
K22: {=(INDEX('Pricing Policies'!A17:F22,MATCH("Vuoto",'Pricing Policies'!A17:A22,0),MATCH(Pricing!B15,'Pricing Policies'!A17:F17,0)))}

Sheet Pricing Policies
A2: SERVIZIO | H2: RETTIFICHE SU BASE CHILOMETRAGGIO
D3: Car (2pax) | E3: Van (3-6 pax) | F3: Full (7-8 pax) | H3: COSTO MACCHINA CON PASSEGGERI
D4: 0.85 | E4: 1 | F4: 1.2 | H4: MAX Addition per 0 km | I4: 120
A5: Low | B5: 0.8 | C5: =Markups!B2*B5 -> 36 | H5: Velocità Decadimento | I5: 45
A6: Average | B6: 1 | C6: =Markups!B2*B6 -> 45 | H6: Velocità attenuazione | I6: 5
A7: High | B7: 1.3 | C7: =Markups!B2*B7 -> 58.5 | H7: Soglia attenuazione | I7: 600
H8: COSTO MACCHINA SOLO DRIVER
A9: ESPERIENZE | H9: MAX Addition per 0 km | I9: 60
D10: Car (2pax) | E10: Van (3-6 pax) | F10: Full (7-8 pax) | H10: Velocità Decadimento | I10: 30
D11: 1 | E11: 1.1 | F11: 1.2 | H11: Velocità attenuazione | I11: 25
A12: Low | B12: 0.5 | C12: =Markups!B3*B12 -> 5 | H12: Soglia attenuazione | I12: 60
A13: Average | B13: 1 | C13: =Markups!B3*B13 -> 10
A14: High | B14: 1.7 | C14: =Markups!B3*B14 -> 17
A16: ESTENSIONE DI SERVIZIO O TRASFERIMENTO
D17: Car (2pax) | E17: Van (3-6 pax) | F17: Full (7-8 pax)
D18: 0.9 | E18: 1 | F18: 1.1
A19: Vuoto | B19: 0.71
A20: Low | B20: 0.85
A21: Average | B21: 1
A22: High | B22: 1.15

Sheet Markups
A1: MARKUPS
A2: Base markup transport | B2: 45
A3: Base markup experiences | B3: 10
A4: Additional tour markup | B4: 25
A5: Only driver markup | B5: 0

Sheet Base Operating Costs
A1: BASE OPERATING COSTS
A2: Fuel Price (€/liter) | B2: =SUM(B8:B9) -> 1.9
A3: Toll Rate (€/km) | B3: ='Annual Fixed Expenses'!B20/'Vehicle Assumptions'!B8 -> 0.0245
A4: Driver Cost (€/hour) | B4: 22
A5: Standard Vehicle Cost (€/hour) | B5: 77
A7: FUEL COST BREAKDOWN (per liter)
A8: Fuel price (per liter) | B8: 1.8
A9: Adblue price(per oil liter) | B9: 0.1
A10: TOTALE COSTO CARBURANTE PER LITRO | B10: =SUM(B8:B9) -> 1.9
A12: CALCULATED COSTS (per km)
A13: Fuel Cost per km | B13: =B2/'Vehicle Assumptions'!B2 -> 0.19
A14: Depreciation per km | B14: =IF(OR('Vehicle Assumptions'!B7=0,'Vehicle Assumptions'!B7>'Vehicle Assumptions'!B6),SUM('Vehicle Depreciation'!I3:I12)/SUM('Vehicle Depreciation'!F3:F12),VLOOKUP('Vehicle Assumptions'!B7,'Vehicle Depreciation'!A2:I12,9)) -> 0.14071721
A15: Costi annuali fissi per km | B15: ='Annual Fixed Expenses'!B14/'Vehicle Assumptions'!B8 -> 0.16100187
A16: Total Variable Cost per km | B16: =B13+B14+B15 -> 0.49171909

Sheet Vehicle Assumptions
A1: VEHICLE ASSUMPTIONS
A2: Fuel Consumption (km/liter) | B2: 10
A3: Vehicle Cost (€) | B3: 67500
A4: Vehicle Residual Value | B4: {=MIN(IF('Vehicle Depreciation'!G3:G12>0,'Vehicle Depreciation'!G3:G12))} -> 28327.869
A5: Vehicle Life (km) | B5: 250000
A6: Vehicle Life (years) | B6: =SUM('Vehicle Depreciation'!F3:F12) -> 3
A7: Vehicle Age (years) | B7: 0
A8: Annual Vehicle Usage (km) | B8: 80000

Sheet Annual Fixed Expenses
A2: ANNUAL FIXED EXPENSES
A3: Assicurazione | B3: 2500
A4: Bollo | B4: 400
A5: Revisione | B5: 100
A6: Tagliandi | B6: 3000
A7: Gomme | B7: ='Annual Fixed Expenses'!B25 -> 2000
A9: Carrozziere | B9: 1000
A10: Meccanico | B10: 1000
A11: Lavaggi | B11: 1200
A12: Incidenza costi forfettari | B12: 0.15
A13: Costi vari forfettari | B13: =SUM(B3:B11)*B12 -> 1680
A14: TOTALE | B14: =SUM(B3:B13) -> 12880.15
A16: COSTO PEDAGGIO PER ANNO
A17: Toll average price (per km) | B17: 0.07
A18: % KM on toll roads | B18: 0.35
A19: Toll share (km) | B19: ='Vehicle Assumptions'!B8*B18 -> 28000
A20: TOTALE COSTO PEDAGGIO PER ANNO | B20: =B17*B19 -> 1960
A22: COSTO GOMME PER ANNO
A23: Cambio ogni KM | B23: 40000
A24: Costo del ricambio gomme | B24: 1000
A25: TOTALE COSTO GOMME PER ANNO | B25: ='Vehicle Assumptions'!B8/B23*B24 -> 2000

Sheet Attenuazione
A1: KM | B1: COSTO | C1: CORRETTO
A2: 0 | B2: =A2*I$21 -> 0 | C2: =B2*((100+$I$22*EXP(-1*A2/$I$23))/100)*IF(A2<$I$25,1,(100-($I$24/100*A2)+($I$25*$I$24/100))/100) -> 0
A3: 10 | B3: =A3*I$21 -> 10 | C3: =B3*((100+$I$22*EXP(-1*A3/$I$23))/100)*IF(A3<$I$25,1,(100-($I$24/100*A3)+($I$25*$I$24/100))/100) -> 19.608849
A4: 20 | B4: =A4*I$21 -> 20 | C4: =B4*((100+$I$22*EXP(-1*A4/$I$23))/100)*IF(A4<$I$25,1,(100-($I$24/100*A4)+($I$25*$I$24/100))/100) -> 35.388329
A5: 30 | B5: =A5*I$21 -> 30 | C5: =B5*((100+$I$22*EXP(-1*A5/$I$23))/100)*IF(A5<$I$25,1,(100-($I$24/100*A5)+($I$25*$I$24/100))/100) -> 48.483016
A6: 40 | B6: =A6*I$21 -> 40 | C6: =B6*((100+$I$22*EXP(-1*A6/$I$23))/100)*IF(A6<$I$25,1,(100-($I$24/100*A6)+($I$25*$I$24/100))/100) -> 59.73339
A7: 50 | B7: =A7*I$21 -> 50 | C7: =B7*((100+$I$22*EXP(-1*A7/$I$23))/100)*IF(A7<$I$25,1,(100-($I$24/100*A7)+($I$25*$I$24/100))/100) -> 69.751579
A8: 60 | B8: =A8*I$21 -> 60 | C8: =B8*((100+$I$22*EXP(-1*A8/$I$23))/100)*IF(A8<$I$25,1,(100-($I$24/100*A8)+($I$25*$I$24/100))/100) -> 78.978994
A9: 70 | B9: =A9*I$21 -> 70 | C9: =B9*((100+$I$22*EXP(-1*A9/$I$23))/100)*IF(A9<$I$25,1,(100-($I$24/100*A9)+($I$25*$I$24/100))/100) -> 87.730055
A10: 80 | B10: =A10*I$21 -> 80 | C10: =B10*((100+$I$22*EXP(-1*A10/$I$23))/100)*IF(A10<$I$25,1,(100-($I$24/100*A10)+($I$25*$I$24/100))/100) -> 96.225278
A11: 90 | B11: =A11*I$21 -> 90 | C11: =B11*((100+$I$22*EXP(-1*A11/$I$23))/100)*IF(A11<$I$25,1,(100-($I$24/100*A11)+($I$25*$I$24/100))/100) -> 104.61621
A12: 100 | B12: =A12*I$21 -> 100 | C12: =B12*((100+$I$22*EXP(-1*A12/$I$23))/100)*IF(A12<$I$25,1,(100-($I$24/100*A12)+($I$25*$I$24/100))/100) -> 113.00416
A13: 110 | B13: =A13*I$21 -> 110 | C13: =B13*((100+$I$22*EXP(-1*A13/$I$23))/100)*IF(A13<$I$25,1,(100-($I$24/100*A13)+($I$25*$I$24/100))/100) -> 121.45421
... A20: 180 | B20: =A20*I$21 -> 180 | C20: =B20*((100+$I$22*EXP(-1*A20/$I$23))/100)*IF(A20<$I$25,1,(100-($I$24/100*A20)+($I$25*$I$24/100))/100) -> 183.95618
A21: 190 | B21: =A21*I$21 -> 190 | C21: =B21*((100+$I$22*EXP(-1*A21/$I$23))/100)*IF(A21<$I$25,1,(100-($I$24/100*A21)+($I$25*$I$24/100))/100) -> 193.34385 | I21: 1
A22: 200 | B22: =A22*I$21 -> 200 | C22: =B22*((100+$I$22*EXP(-1*A22/$I$23))/100)*IF(A22<$I$25,1,(100-($I$24/100*A22)+($I$25*$I$24/100))/100) -> 202.81847 | H22: MAX Addition per 0 km | I22: 120
A23: 210 | B23: =A23*I$21 -> 210 | C23: =B23*((100+$I$22*EXP(-1*A23/$I$23))/100)*IF(A23<$I$25,1,(100-($I$24/100*A23)+($I$25*$I$24/100))/100) -> 212.3697 | H23: Velocità Decadimento | I23: 45
A24: 220 | B24: =A24*I$21 -> 220 | C24: =B24*((100+$I$22*EXP(-1*A24/$I$23))/100)*IF(A24<$I$25,1,(100-($I$24/100*A24)+($I$25*$I$24/100))/100) -> 221.98786 | H24: Velocità attenuazione | I24: 5
A25: 230 | B25: =A25*I$21 -> 230 | C25: =B25*((100+$I$22*EXP(-1*A25/$I$23))/100)*IF(A25<$I$25,1,(100-($I$24/100*A25)+($I$25*$I$24/100))/100) -> 231.66411 | H25: Soglia attenuazione | I25: 600
A26: 240 | B26: =A26*I$21 -> 240 | C26: =B26*((100+$I$22*EXP(-1*A26/$I$23))/100)*IF(A26<$I$25,1,(100-($I$24/100*A26)+($I$25*$I$24/100))/100) -> 241.39045
A27: 250 | B27: =A27*I$21 -> 250 | C27: =B27*((100+$I$22*EXP(-1*A27/$I$23))/100)*IF(A27<$I$25,1,(100-($I$24/100*A27)+($I$25*$I$24/100))/100) -> 251.15978
A28: 260 | B28: =A28*I$21 -> 260 | C28: =B28*((100+$I$22*EXP(-1*A28/$I$23))/100)*IF(A28<$I$25,1,(100-($I$24/100*A28)+($I$25*$I$24/100))/100) -> 260.96582
A29: 270 | B29: =A29*I$21 -> 270 | C29: =B29*((100+$I$22*EXP(-1*A29/$I$23))/100)*IF(A29<$I$25,1,(100-($I$24/100*A29)+($I$25*$I$24/100))/100) -> 270.80312
A30: 280 | B30: =A30*I$21 -> 280 | C30: =B30*((100+$I$22*EXP(-1*A30/$I$23))/100)*IF(A30<$I$25,1,(100-($I$24/100*A30)+($I$25*$I$24/100))/100) -> 280.6669
A31: 290 | B31: =A31*I$21 -> 290 | C31: =B31*((100+$I$22*EXP(-1*A31/$I$23))/100)*IF(A31<$I$25,1,(100-($I$24/100*A31)+($I$25*$I$24/100))/100) -> 290.55309
A32: 300 | B32: =A32*I$21 -> 300 | C32: =B32*((100+$I$22*EXP(-1*A32/$I$23))/100)*IF(A32<$I$25,1,(100-($I$24/100*A32)+($I$25*$I$24/100))/100) -> 300.45815
A33: 310 | B33: =A33*I$21 -> 310 | C33: =B33*((100+$I$22*EXP(-1*A33/$I$23))/100)*IF(A33<$I$25,1,(100-($I$24/100*A33)+($I$25*$I$24/100))/100) -> 310.37908
A34: 320 | B34: =A34*I$21 -> 320 | C34: =B34*((100+$I$22*EXP(-1*A34/$I$23))/100)*IF(A34<$I$25,1,(100-($I$24/100*A34)+($I$25*$I$24/100))/100) -> 320.31334
A35: 330 | B35: =A35*I$21 -> 330 | C35: =B35*((100+$I$22*EXP(-1*A35/$I$23))/100)*IF(A35<$I$25,1,(100-($I$24/100*A35)+($I$25*$I$24/100))/100) -> 330.25874
A36: 340 | B36: =A36*I$21 -> 340 | C36: =B36*((100+$I$22*EXP(-1*A36/$I$23))/100)*IF(A36<$I$25,1,(100-($I$24/100*A36)+($I$25*$I$24/100))/100) -> 340.21346
A37: 350 | B37: =A37*I$21 -> 350 | C37: =B37*((100+$I$22*EXP(-1*A37/$I$23))/100)*IF(A37<$I$25,1,(100-($I$24/100*A37)+($I$25*$I$24/100))/100) -> 350.17596
... A102: 1000 | B102: =A102*I$21 -> 1000 | C102: =B102*((100+$I$22*EXP(-1*A102/$I$23))/100)*IF(A102<$I$25,1,(100-($I$24/100*A102)+($I$25*$I$24/100))/100) -> 800

Sheet Tour List
A1: NOME | C1: DURATION | D1: HRs | E1: KMs | F1: TOLL | G1: ESP A | H1: ESP B | I1: ESP C | J1: ESP D | K1: ESPERIENZE p.p.
A2: Personalizzato | D2: 0 | E2: 0 | F2: 0 | G2: 0 | H2: 0 | I2: 0 | J2: 0 | K2: =SUM(G2:J2) -> 0
A3: =CONCATENATE(B3, " - ",C3) -> Chianti Classico - TOUR HD | B3: Chianti Classico | C3: TOUR HD | D3: 5 | E3: 150 | F3: 0 | G3: 50 | H3: 20 | I3: 0 | J3: 0 | K3: =SUM(G3:J3) -> 70
A4: =CONCATENATE(B4, " - ",C4) -> Montalcino - TOUR HD | B4: Montalcino | C4: TOUR HD | D4: 5 | E4: 150 | F4: 0 | G4: 50 | H4: 20 | I4: 0 | J4: 0 | K4: =SUM(G4:J4) -> 70
A5: =CONCATENATE(B5, " - ",C5) -> Monteriggioni-SanGi - TOUR HD | B5: Monteriggioni-SanGi | C5: TOUR HD | D5: 5 | E5: 150 | F5: 0
A6: =CONCATENATE(B6, " - ",C6) -> Modena - TOUR FD+ | B6: Modena | C6: TOUR FD+ | D6: 10 | E6: 400 | F6: 20
A7: =CONCATENATE(B7, " - ",C7) -> Bolgheri - TOUR FD+ | B7: Bolgheri | C7: TOUR FD+ | D7: 10 | E7: 400 | F7: 0
A8: =CONCATENATE(B8, " - ",C8) -> Suvereto - TOUR FD+ | B8: Suvereto | C8: TOUR FD+ | D8: 10 | E8: 400 | F8: 0
A9: =CONCATENATE(B9, " - ",C9) -> Chianti Classico - TOUR FD | B9: Chianti Classico | C9: TOUR FD | D9: 8 | E9: 250 | F9: 0 | G9: 50 | H9: 20 | I9: 0 | J9: 0 | K9: =SUM(G9:J9) -> 70
A10: =CONCATENATE(B10, " - ",C10) -> Montalcino-Pienza - TOUR FD | B10: Montalcino-Pienza | C10: TOUR FD | D10: 9 | E10: 250 | F10: 0 | G10: 50 | H10: 20 | I10: 0 | J10: 0 | K10: =SUM(G10:J10) -> 70
A11: =CONCATENATE(B11, " - ",C11) -> Pisa-Lucca - TOUR FD | B11: Pisa-Lucca | C11: TOUR FD | D11: 9 | E11: 300 | F11: 0
A12: =CONCATENATE(B12, " - ",C12) -> Monteriggioni-SanGi-Volterra - TOUR FD | B12: Monteriggioni-SanGi-Volterra | C12: TOUR FD | D12: 9 | E12: 250 | F12: 0
A13: =CONCATENATE(B13, " - ",C13) -> Assisi - TOUR FD | B13: Assisi | C13: TOUR FD | D13: 9 | E13: 300 | F13: 0
A14: =CONCATENATE(B14, " - ",C14) -> Siena - TRF | B14: Siena | C14: TRF | D14: 1 | E14: 10 | F14: 0
A15: =CONCATENATE(B15, " - ",C15) -> Siena dintorni - TRF | B15: Siena dintorni | C15: TRF | D15: 2 | E15: 30 | F15: 0
A16: =CONCATENATE(B16, " - ",C16) -> Arezzo - TRF | B16: Arezzo | C16: TRF | D16: 3 | E16: 180 | F16: 0
A17: =CONCATENATE(B17, " - ",C17) -> Chiusi - TRF | B17: Chiusi | C17: TRF | D17: 3 | E17: 180 | F17: 5
A18: =CONCATENATE(B18, " - ",C18) -> Civitavecchia - TRF | B18: Civitavecchia | C18: TRF | D18: 5 | E18: 370 | F18: 5
A19: =CONCATENATE(B19, " - ",C19) -> Cortona - TRF | B19: Cortona | C19: TRF | D19: 3 | E19: 150 | F19: 0
A20: =CONCATENATE(B20, " - ",C20) -> Grosseto - TRF | B20: Grosseto | C20: TRF | D20: 3 | E20: 150 | F20: 0
A21: =CONCATENATE(B21, " - ",C21) -> Como - TRF | B21: Como | C21: TRF | D21: 10 | E21: 840 | F21: 65
A22: =CONCATENATE(B22, " - ",C22) -> Bologna - TRF | B22: Bologna | C22: TRF | D22: 5 | E22: 340 | F22: 20
... A43: =CONCATENATE(B43, " - ",C43) -> Venezia - TRF | B43: Venezia | C43: TRF | D43: 8 | E43: 640 | F43: 45

Sheet Copia di Tour List
M1: Soglia Attenuazione | N1: Tasso attenuazione | O1: Massimo aumento | P1: Velocità decadimento | T1: Selezionare scenario di prezzo: L = LOW; A = AVERAGE; H = HIGH; C = CAR; V = VAN; F = FULL Selezionare solo una colonna | AC1: Pax riferimento | AE1: Selezionare scenario di prezzo: L = LOW; A = AVERAGE; H = HIGH; C = CAR; V = VAN; F = FULL Selezionare solo una colonna | AR1: VAT riferimento | AT1: Card Fees riferimento | AY1: % per Driver
M2: 600 | N2: 10 | O2: 120 | P2: 45 | T2: FALSE | U2: TRUE | V2: FALSE | W2: FALSE | X2: FALSE | Y2: FALSE | Z2: FALSE | AA2: FALSE | AB2: FALSE | AC2: 2 | AE2: FALSE | AF2: TRUE | AG2: FALSE | AH2: FALSE | AI2: FALSE | AJ2: FALSE | AK2: FALSE | AL2: FALSE | AM2: FALSE | AR2: 0.1 | AT2: 0.05 | AY2: 0.25
A3: NOME | C3: DURATION | D3: HRs | E3: KMs | F3: TOLL | G3: ESP A | H3: ESP B | I3: ESP C | J3: ESP D | K3: ESPERIENZE p.p. | M3: Fuel Cost | N3: Depreciation | O3: Costi fissi | P3: Driver Cost | Q3: Tolls | R3: Cost Transport | S3: Cost TransportCorrected | T3: CL | U3: CA | V3: CH | W3: VL | X3: VA | Y3: VH | Z3: FL | AA3: FA | AB3: FH | AC3: Pax | AD3: Costo Esperience | AE3: LL | AF3: LA | AG3: LH | AH3: AL | AI3: AH | AJ3: AA | AK3: HL | AL3: HA | AM3: HH | AN3: TOT TRASP | AO3: TOT ESPERIENZE | AP3: TOT CALCOLATO | AQ3: TOTALE | AR3: VAT | AS3: VAT € | AT3: CC FEES | AU3: CC FEES € | AW3: TOTALE VENDITA | AX3: IMPONIBILE | AY3: COSTO DRIVER | AZ3: COSTO ORA | BA3: COSTO CORRETTO | BC3: COSTO MEDIO | BD3: =AVERAGE(AZ5:AZ45) -> 19.460154 | BF3: 1728 | BG3: =BD5*BF3 -> 33022.173
A4: Personalizzato | D4: 0 | E4: 0 | F4: 0 | G4: 0 | H4: 0 | I4: 0 | J4: 0 | K4: =SUM(G4:J4) -> 0 | M4: =(E4)*'Base Operating Costs'!$B$13 -> 0 | N4: =(E4)*'Base Operating Costs'!$B$14 -> 0 | O4: ='Base Operating Costs'!$B$15*(E4) -> 0 | P4: =D4*'Base Operating Costs'!$B$4 -> 0 | Q4: =F4 -> 0 | S4: =M4+N4+O4+P4+Q4 -> 0 | T4: =S4*(1+'Pricing Policies'!$C$5/100)*'Pricing Policies'!$D$4*IF($C4="TRF",1,(1+Markups!$B$4/100)) -> 0 | U4: =S4*(1+'Pricing Policies'!$C$5/100)*'Pricing Policies'!$E$4*IF($C4="TRF",1,(1+Markups!$B$4/100)) -> 0 | V4: =S4*(1+'Pricing Policies'!$C$5/100)*'Pricing Policies'!$F$4*IF($C4="TRF",1,(1+Markups!$B$4/100)) -> 0 | W4: =S4*(1+'Pricing Policies'!$C$6/100)*'Pricing Policies'!$D$4*IF($C4="TRF",1,(1+Markups!$B$4/100)) -> 0 | X4: =S4*(1+'Pricing Policies'!$C$6/100)*'Pricing Policies'!$E$4*IF($C4="TRF",1,(1+Markups!$B$4/100)) -> 0 | Y4: =S4*(1+'Pricing Policies'!$C$6/100)*'Pricing Policies'!$F$4*IF($C4="TRF",1,(1+Markups!$B$4/100)) -> 0 | Z4: =S4*(1+'Pricing Policies'!$C$7/100)*'Pricing Policies'!$D$4*IF($C4="TRF",1,(1+Markups!$B$4/100)) -> 0 | AA4: =S4*(1+'Pricing Policies'!$C$7/100)*'Pricing Policies'!$E$4*IF($C4="TRF",1,(1+Markups!$B$4/100)) -> 0 | AB4: =S4*(1+'Pricing Policies'!$C$7/100)*'Pricing Policies'!$F$4*IF($C4="TRF",1,(1+Markups!$B$4/100)) -> 0 | AC4: =AC$2 -> 2 | AD4: =AC4*K4 -> 0 | AE4: =AD4*(1+'Pricing Policies'!$C$12/100)*'Pricing Policies'!$D$11 -> 0 | AF4: =AD4*(1+'Pricing Policies'!$C$12/100)*'Pricing Policies'!$E$11 -> 0 | AG4: =AD4*(1+'Pricing Policies'!$C$12/100)*'Pricing Policies'!$F$11 -> 0 | AH4: =AD4*(1+'Pricing Policies'!$C$13/100)*'Pricing Policies'!$D$11 -> 0 | AI4: =AD4*(1+'Pricing Policies'!$C$13/100)*'Pricing Policies'!$E$11 -> 0 | AJ4: =AD4*(1+'Pricing Policies'!$C$13/100)*'Pricing Policies'!$F$11 -> 0 | AK4: =AD4*(1+'Pricing Policies'!$C$14/100)*'Pricing Policies'!$D$11 -> 0 | AL4: =AD4*(1+'Pricing Policies'!$C$14/100)*'Pricing Policies'!$E$11 -> 0 | AM4: =AD4*(1+'Pricing Policies'!$C$14/100)*'Pricing Policies'!$F$11 -> 0 | AN4: =(T$2*T4+U$2*U4+V$2*V4+W$2*W4+X$2*X4+Y$2*Y4+Z$2*Z4+AA$2*AA4+AB$2*AB4) -> 0 | AO4: =(AE$2*AE4+AF$2*AF4+AG$2*AG4+AH$2*AH4+AI$2*AI4+AJ$2*AJ4+AK$2*AK4+AL$2*AL4+AM$2*AM4) -> 0 | AQ4: =AN4+AO4 -> 0 | AR4: =AR$2 -> 0.1 | AS4: =AQ4*AR4 -> 0 | AT4: =AT$2 -> 0.05 | AU4: =(AQ4+AS4)*AT4 -> 0 | AW4: =AQ4+AS4+AU4 -> 0 | AX4: =AW4-AU4-AS4-AD4 -> 0 | AY4: =AX4*AY$2 -> 0 | AZ4: =AY4/D4 -> #DIV/0!
A5: =CONCATENATE(B5, " - ",C5) -> Chianti Classico - TOUR HD | B5: Chianti Classico | C5: TOUR HD | D5: 5 | E5: 150 | F5: 0 | G5: 50 | H5: 20 | I5: 0 | J5: 0 | K5: =SUM(G5:J5) -> 70 | M5: =(E5)*'Base Operating Costs'!$B$13 -> 28.5 | N5: =(E5)*'Base Operating Costs'!$B$14 -> 21.107582 | O5: ='Base Operating Costs'!$B$15*(E5) -> 24.150281 | P5: =D5*'Base Operating Costs'!$B$4 -> 110 | Q5: =F5 -> 0 | R5: =M5+N5+O5+P5+Q5 -> 183.75786 | S5: =R5*((100+O$2*EXP(-1*E5/P$2))/100)*IF(E5<M$2,1,(1-(N$2/100))) -> 191.62432 | T5: =S5*(1+'Pricing Policies'!$C$5/100)*'Pricing Policies'!$D$4*IF($C5="TRF",1,(1+Markups!$B$4/100)) -> 276.89714 | U5: =S5*(1+'Pricing Policies'!$C$5/100)*'Pricing Policies'!$E$4*IF($C5="TRF",1,(1+Markups!$B$4/100)) -> 325.76134 | V5: =S5*(1+'Pricing Policies'!$C$5/100)*'Pricing Policies'!$F$4*IF($C5="TRF",1,(1+Markups!$B$4/100)) -> 390.9136 | W5: =S5*(1+'Pricing Policies'!$C$6/100)*'Pricing Policies'!$D$4*IF($C5="TRF",1,(1+Markups!$B$4/100)) -> 295.22121 | X5: =S5*(1+'Pricing Policies'!$C$6/100)*'Pricing Policies'!$E$4*IF($C5="TRF",1,(1+Markups!$B$4/100)) -> 347.31907 | Y5: =S5*(1+'Pricing Policies'!$C$6/100)*'Pricing Policies'!$F$4*IF($C5="TRF",1,(1+Markups!$B$4/100)) -> 416.78289 | Z5: =S5*(1+'Pricing Policies'!$C$7/100)*'Pricing Policies'!$D$4*IF($C5="TRF",1,(1+Markups!$B$4/100)) -> 322.70732 | AA5: =S5*(1+'Pricing Policies'!$C$7/100)*'Pricing Policies'!$E$4*IF($C5="TRF",1,(1+Markups!$B$4/100)) -> 379.65567 | AB5: =S5*(1+'Pricing Policies'!$C$7/100)*'Pricing Policies'!$F$4*IF($C5="TRF",1,(1+Markups!$B$4/100)) -> 455.58681 | AC5: 0 | AD5: =AC5*K5 -> 0 | AE5: =AD5*(1+'Pricing Policies'!$C$12/100)*'Pricing Policies'!$D$11 -> 0 | AF5: =AD5*(1+'Pricing Policies'!$C$12/100)*'Pricing Policies'!$E$11 -> 0 | AG5: =AD5*(1+'Pricing Policies'!$C$12/100)*'Pricing Policies'!$F$11 -> 0 | AH5: =AD5*(1+'Pricing Policies'!$C$13/100)*'Pricing Policies'!$D$11 -> 0 | AI5: =AD5*(1+'Pricing Policies'!$C$13/100)*'Pricing Policies'!$E$11 -> 0 | AJ5: =AD5*(1+'Pricing Policies'!$C$13/100)*'Pricing Policies'!$F$11 -> 0 | AK5: =AD5*(1+'Pricing Policies'!$C$14/100)*'Pricing Policies'!$D$11 -> 0 | AL5: =AD5*(1+'Pricing Policies'!$C$14/100)*'Pricing Policies'!$E$11 -> 0 | AM5: =AD5*(1+'Pricing Policies'!$C$14/100)*'Pricing Policies'!$F$11 -> 0 | AN5: =(T$2*T5+U$2*U5+V$2*V5+W$2*W5+X$2*X5+Y$2*Y5+Z$2*Z5+AA$2*AA5+AB$2*AB5) -> 325.76134 | AO5: =(AE$2*AE5+AF$2*AF5+AG$2*AG5+AH$2*AH5+AI$2*AI5+AJ$2*AJ5+AK$2*AK5+AL$2*AL5+AM$2*AM5) -> 0 | AP5: =AN5+AO5 -> 325.76134 | AQ5: =CEILING(AP5,5) -> 330 | AR5: =AR$2 -> 0.1 | AS5: =AQ5*AR5 -> 33 | AT5: =AT$2 -> 0.05 | AU5: =(AQ5+AS5)*AT5 -> 18.15 | AV5: =AQ5+AS5+AU5 -> 381.15 | AW5: =CEILING(AV5,5) -> 385 | AX5: =AW5-AU5-AS5-AD5 -> 333.85 | AY5: =AX5*AY$2 -> 83.4625 | AZ5: =AY5/D5 -> 16.6925 | BA5: =IF(AZ5<BD$9,BD$9,IF(AZ5>BD$10,BD$10,AZ5)) -> 16.6925 | BC5: COSTO MEDIO CORRETTO | BD5: =AVERAGE(BA5:BA45) -> 19.110054
A6: =CONCATENATE(B6, " - ",C6) -> Montalcino - TOUR HD | B6: Montalcino | C6: TOUR HD | D6: 5 | E6: 150 | F6: 0 | G6: 50 | H6: 20 | I6: 0 | J6: 0 | K6: =SUM(G6:J6) -> 70 | M6: =(E6)*'Base Operating Costs'!$B$13 -> 28.5 | N6: =(E6)*'Base Operating Costs'!$B$14 -> 21.107582 | O6: ='Base Operating Costs'!$B$15*(E6) -> 24.150281 | P6: =D6*'Base Operating Costs'!$B$4 -> 110 | Q6: =F6 -> 0 | R6: =M6+N6+O6+P6+Q6 -> 183.75786 | S6: =R6*((100+O$2*EXP(-1*E6/P$2))/100)*IF(E6<M$2,1,(1-(N$2/100))) -> 191.62432 | T6: =S6*(1+'Pricing Policies'!$C$5/100)*'Pricing Policies'!$D$4*IF($C6="TRF",1,(1+Markups!$B$4/100)) -> 276.89714 | U6: =S6*(1+'Pricing Policies'!$C$5/100)*'Pricing Policies'!$E$4*IF($C6="TRF",1,(1+Markups!$B$4/100)) -> 325.76134 | V6: =S6*(1+'Pricing Policies'!$C$5/100)*'Pricing Policies'!$F$4*IF($C6="TRF",1,(1+Markups!$B$4/100)) -> 390.9136 | W6: =S6*(1+'Pricing Policies'!$C$6/100)*'Pricing Policies'!$D$4*IF($C6="TRF",1,(1+Markups!$B$4/100)) -> 295.22121 | X6: =S6*(1+'Pricing Policies'!$C$6/100)*'Pricing Policies'!$E$4*IF($C6="TRF",1,(1+Markups!$B$4/100)) -> 347.31907 | Y6: =S6*(1+'Pricing Policies'!$C$6/100)*'Pricing Policies'!$F$4*IF($C6="TRF",1,(1+Markups!$B$4/100)) -> 416.78289 | Z6: =S6*(1+'Pricing Policies'!$C$7/100)*'Pricing Policies'!$D$4*IF($C6="TRF",1,(1+Markups!$B$4/100)) -> 322.70732 | AA6: =S6*(1+'Pricing Policies'!$C$7/100)*'Pricing Policies'!$E$4*IF($C6="TRF",1,(1+Markups!$B$4/100)) -> 379.65567 | AB6: =S6*(1+'Pricing Policies'!$C$7/100)*'Pricing Policies'!$F$4*IF($C6="TRF",1,(1+Markups!$B$4/100)) -> 455.58681 | AC6: =AC$2 -> 2 | AD6: =AC6*K6 -> 140 | AE6: =AD6*(1+'Pricing Policies'!$C$12/100)*'Pricing Policies'!$D$11 -> 147 | AF6: =AD6*(1+'Pricing Policies'!$C$12/100)*'Pricing Policies'!$E$11 -> 161.7 | AG6: =AD6*(1+'Pricing Policies'!$C$12/100)*'Pricing Policies'!$F$11 -> 176.4 | AH6: =AD6*(1+'Pricing Policies'!$C$13/100)*'Pricing Policies'!$D$11 -> 154 | AI6: =AD6*(1+'Pricing Policies'!$C$13/100)*'Pricing Policies'!$E$11 -> 169.4 | AJ6: =AD6*(1+'Pricing Policies'!$C$13/100)*'Pricing Policies'!$F$11 -> 184.8 | AK6: =AD6*(1+'Pricing Policies'!$C$14/100)*'Pricing Policies'!$D$11 -> 163.8 | AL6: =AD6*(1+'Pricing Policies'!$C$14/100)*'Pricing Policies'!$E$11 -> 180.18 | AM6: =AD6*(1+'Pricing Policies'!$C$14/100)*'Pricing Policies'!$F$11 -> 196.56 | AN6: =(T$2*T6+U$2*U6+V$2*V6+W$2*W6+X$2*X6+Y$2*Y6+Z$2*Z6+AA$2*AA6+AB$2*AB6) -> 325.76134 | AO6: =(AE$2*AE6+AF$2*AF6+AG$2*AG6+AH$2*AH6+AI$2*AI6+AJ$2*AJ6+AK$2*AK6+AL$2*AL6+AM$2*AM6) -> 161.7 | AP6: =AN6+AO6 -> 487.46134 | AQ6: =CEILING(AP6,5) -> 490 | AR6: =AR$2 -> 0.1 | AS6: =AQ6*AR6 -> 49 | AT6: =AT$2 -> 0.05 | AU6: =(AQ6+AS6)*AT6 -> 26.95 | AV6: =AQ6+AS6+AU6 -> 565.95 | AW6: =CEILING(AV6,5) -> 570 | AX6: =AW6-AU6-AS6-AD6 -> 354.05 | AY6: =AX6*AY$2 -> 88.5125 | AZ6: =AY6/D6 -> 17.7025 | BA6: =IF(AZ6<BD$9,BD$9,IF(AZ6>BD$10,BD$10,AZ6)) -> 17.7025 | BC6: COSTO MINIMO | BD6: =MIN(AZ5:AZ45) -> 15.409722
A7: =CONCATENATE(B7, " - ",C7) -> Monteriggioni-SanGi - TOUR HD | B7: Monteriggioni-SanGi | C7: TOUR HD | D7: 5 | E7: 150 | F7: 0 | M7: =(E7)*'Base Operating Costs'!$B$13 -> 28.5 | N7: =(E7)*'Base Operating Costs'!$B$14 -> 21.107582 | O7: ='Base Operating Costs'!$B$15*(E7) -> 24.150281 | P7: =D7*'Base Operating Costs'!$B$4 -> 110 | Q7: =F7 -> 0 | R7: =M7+N7+O7+P7+Q7 -> 183.75786 | S7: =R7*((100+O$2*EXP(-1*E7/P$2))/100)*IF(E7<M$2,1,(1-(N$2/100))) -> 191.62432 | T7: =S7*(1+'Pricing Policies'!$C$5/100)*'Pricing Policies'!$D$4*IF($C7="TRF",1,(1+Markups!$B$4/100)) -> 276.89714 | U7: =S7*(1+'Pricing Policies'!$C$5/100)*'Pricing Policies'!$E$4*IF($C7="TRF",1,(1+Markups!$B$4/100)) -> 325.76134 | V7: =S7*(1+'Pricing Policies'!$C$5/100)*'Pricing Policies'!$F$4*IF($C7="TRF",1,(1+Markups!$B$4/100)) -> 390.9136 | W7: =S7*(1+'Pricing Policies'!$C$6/100)*'Pricing Policies'!$D$4*IF($C7="TRF",1,(1+Markups!$B$4/100)) -> 295.22121 | X7: =S7*(1+'Pricing Policies'!$C$6/100)*'Pricing Policies'!$E$4*IF($C7="TRF",1,(1+Markups!$B$4/100)) -> 347.31907 | Y7: =S7*(1+'Pricing Policies'!$C$6/100)*'Pricing Policies'!$F$4*IF($C7="TRF",1,(1+Markups!$B$4/100)) -> 416.78289 | Z7: =S7*(1+'Pricing Policies'!$C$7/100)*'Pricing Policies'!$D$4*IF($C7="TRF",1,(1+Markups!$B$4/100)) -> 322.70732 | AA7: =S7*(1+'Pricing Policies'!$C$7/100)*'Pricing Policies'!$E$4*IF($C7="TRF",1,(1+Markups!$B$4/100)) -> 379.65567 | AB7: =S7*(1+'Pricing Policies'!$C$7/100)*'Pricing Policies'!$F$4*IF($C7="TRF",1,(1+Markups!$B$4/100)) -> 455.58681 | AC7: =AC$2 -> 2 | AD7: =AC7*K7 -> 0 | AE7: =AD7*(1+'Pricing Policies'!$C$12/100)*'Pricing Policies'!$D$11 -> 0 | AF7: =AD7*(1+'Pricing Policies'!$C$12/100)*'Pricing Policies'!$E$11 -> 0 | AG7: =AD7*(1+'Pricing Policies'!$C$12/100)*'Pricing Policies'!$F$11 -> 0 | AH7: =AD7*(1+'Pricing Policies'!$C$13/100)*'Pricing Policies'!$D$11 -> 0 | AI7: =AD7*(1+'Pricing Policies'!$C$13/100)*'Pricing Policies'!$E$11 -> 0 | AJ7: =AD7*(1+'Pricing Policies'!$C$13/100)*'Pricing Policies'!$F$11 -> 0 | AK7: =AD7*(1+'Pricing Policies'!$C$14/100)*'Pricing Policies'!$D$11 -> 0 | AL7: =AD7*(1+'Pricing Policies'!$C$14/100)*'Pricing Policies'!$E$11 -> 0 | AM7: =AD7*(1+'Pricing Policies'!$C$14/100)*'Pricing Policies'!$F$11 -> 0 | AN7: =(T$2*T7+U$2*U7+V$2*V7+W$2*W7+X$2*X7+Y$2*Y7+Z$2*Z7+AA$2*AA7+AB$2*AB7) -> 325.76134 | AO7: =(AE$2*AE7+AF$2*AF7+AG$2*AG7+AH$2*AH7+AI$2*AI7+AJ$2*AJ7+AK$2*AK7+AL$2*AL7+AM$2*AM7) -> 0 | AP7: =AN7+AO7 -> 325.76134 | AQ7: =CEILING(AP7,5) -> 330 | AR7: =AR$2 -> 0.1 | AS7: =AQ7*AR7 -> 33 | AT7: =AT$2 -> 0.05 | AU7: =(AQ7+AS7)*AT7 -> 18.15 | AV7: =AQ7+AS7+AU7 -> 381.15 | AW7: =CEILING(AV7,5) -> 385 | AX7: =AW7-AU7-AS7-AD7 -> 333.85 | AY7: =AX7*AY$2 -> 83.4625 | AZ7: =AY7/D7 -> 16.6925 | BA7: =IF(AZ7<BD$9,BD$9,IF(AZ7>BD$10,BD$10,AZ7)) -> 16.6925 | BC7: COSTO MASSIMO | BD7: =MAX(AZ5:AZ45) -> 29.29375
A8: =CONCATENATE(B8, " - ",C8) -> Modena - TOUR FD+ | B8: Modena | C8: TOUR FD+ | D8: 10 | E8: 400 | F8: 20 | M8: =(E8)*'Base Operating Costs'!$B$13 -> 76 | N8: =(E8)*'Base Operating Costs'!$B$14 -> 56.286885 | O8: ='Base Operating Costs'!$B$15*(E8) -> 64.40075 | P8: =D8*'Base Operating Costs'!$B$4 -> 220 | Q8: =F8 -> 20 | R8: =M8+N8+O8+P8+Q8 -> 436.68764 | S8: =R8*((100+O$2*EXP(-1*E8/P$2))/100)*IF(E8<M$2,1,(1-(N$2/100))) -> 436.75991 | T8: =S8*(1+'Pricing Policies'!$C$5/100)*'Pricing Policies'!$D$4*IF($C8="TRF",1,(1+Markups!$B$4/100)) -> 631.11806 | U8: =S8*(1+'Pricing Policies'!$C$5/100)*'Pricing Policies'!$E$4*IF($C8="TRF",1,(1+Markups!$B$4/100)) -> 742.49184 | V8: =S8*(1+'Pricing Policies'!$C$5/100)*'Pricing Policies'!$F$4*IF($C8="TRF",1,(1+Markups!$B$4/100)) -> 890.99021 | W8: =S8*(1+'Pricing Policies'!$C$6/100)*'Pricing Policies'!$D$4*IF($C8="TRF",1,(1+Markups!$B$4/100)) -> 672.88323 | X8: =S8*(1+'Pricing Policies'!$C$6/100)*'Pricing Policies'!$E$4*IF($C8="TRF",1,(1+Markups!$B$4/100)) -> 791.62733 | Y8: =S8*(1+'Pricing Policies'!$C$6/100)*'Pricing Policies'!$F$4*IF($C8="TRF",1,(1+Markups!$B$4/100)) -> 949.95279 | Z8: =S8*(1+'Pricing Policies'!$C$7/100)*'Pricing Policies'!$D$4*IF($C8="TRF",1,(1+Markups!$B$4/100)) -> 735.53098 | AA8: =S8*(1+'Pricing Policies'!$C$7/100)*'Pricing Policies'!$E$4*IF($C8="TRF",1,(1+Markups!$B$4/100)) -> 865.33056 | AB8: =S8*(1+'Pricing Policies'!$C$7/100)*'Pricing Policies'!$F$4*IF($C8="TRF",1,(1+Markups!$B$4/100)) -> 1038.3967 | AC8: =AC$2 -> 2 | AD8: =AC8*K8 -> 0 | AE8: =AD8*(1+'Pricing Policies'!$C$12/100)*'Pricing Policies'!$D$11 -> 0 | AF8: =AD8*(1+'Pricing Policies'!$C$12/100)*'Pricing Policies'!$E$11 -> 0 | AG8: =AD8*(1+'Pricing Policies'!$C$12/100)*'Pricing Policies'!$F$11 -> 0 | AH8: =AD8*(1+'Pricing Policies'!$C$13/100)*'Pricing Policies'!$D$11 -> 0 | AI8: =AD8*(1+'Pricing Policies'!$C$13/100)*'Pricing Policies'!$E$11 -> 0 | AJ8: =AD8*(1+'Pricing Policies'!$C$13/100)*'Pricing Policies'!$F$11 -> 0 | AK8: =AD8*(1+'Pricing Policies'!$C$14/100)*'Pricing Policies'!$D$11 -> 0 | AL8: =AD8*(1+'Pricing Policies'!$C$14/100)*'Pricing Policies'!$E$11 -> 0 | AM8: =AD8*(1+'Pricing Policies'!$C$14/100)*'Pricing Policies'!$F$11 -> 0 | AN8: =(T$2*T8+U$2*U8+V$2*V8+W$2*W8+X$2*X8+Y$2*Y8+Z$2*Z8+AA$2*AA8+AB$2*AB8) -> 742.49184 | AO8: =(AE$2*AE8+AF$2*AF8+AG$2*AG8+AH$2*AH8+AI$2*AI8+AJ$2*AJ8+AK$2*AK8+AL$2*AL8+AM$2*AM8) -> 0 | AP8: =AN8+AO8 -> 742.49184 | AQ8: =CEILING(AP8,5) -> 745 | AR8: =AR$2 -> 0.1 | AS8: =AQ8*AR8 -> 74.5 | AT8: =AT$2 -> 0.05 | AU8: =(AQ8+AS8)*AT8 -> 40.975 | AV8: =AQ8+AS8+AU8 -> 860.475 | AW8: =CEILING(AV8,5) -> 865 | AX8: =AW8-AU8-AS8-AD8 -> 749.525 | AY8: =AX8*AY$2 -> 187.38125 | AZ8: =AY8/D8 -> 18.738125 | BA8: =IF(AZ8<BD$9,BD$9,IF(AZ8>BD$10,BD$10,AZ8)) -> 18.738125
A9: =CONCATENATE(B9, " - ",C9) -> Bolgheri - TOUR FD+ | B9: Bolgheri | C9: TOUR FD+ | D9: 10 | E9: 400 | F9: 0 | M9: =(E9)*'Base Operating Costs'!$B$13 -> 76 | N9: =(E9)*'Base Operating Costs'!$B$14 -> 56.286885 | O9: ='Base Operating Costs'!$B$15*(E9) -> 64.40075 | P9: =D9*'Base Operating Costs'!$B$4 -> 220 | Q9: =F9 -> 0 | R9: =M9+N9+O9+P9+Q9 -> 416.68764 | S9: =R9*((100+O$2*EXP(-1*E9/P$2))/100)*IF(E9<M$2,1,(1-(N$2/100))) -> 416.7566 | T9: =S9*(1+'Pricing Policies'!$C$5/100)*'Pricing Policies'!$D$4*IF($C9="TRF",1,(1+Markups!$B$4/100)) -> 602.21328 | U9: =S9*(1+'Pricing Policies'!$C$5/100)*'Pricing Policies'!$E$4*IF($C9="TRF",1,(1+Markups!$B$4/100)) -> 708.48621 | V9: =S9*(1+'Pricing Policies'!$C$5/100)*'Pricing Policies'!$F$4*IF($C9="TRF",1,(1+Markups!$B$4/100)) -> 850.18345 | W9: =S9*(1+'Pricing Policies'!$C$6/100)*'Pricing Policies'!$D$4*IF($C9="TRF",1,(1+Markups!$B$4/100)) -> 642.06563 | X9: =S9*(1+'Pricing Policies'!$C$6/100)*'Pricing Policies'!$E$4*IF($C9="TRF",1,(1+Markups!$B$4/100)) -> 755.37133 | Y9: =S9*(1+'Pricing Policies'!$C$6/100)*'Pricing Policies'!$F$4*IF($C9="TRF",1,(1+Markups!$B$4/100)) -> 906.44559 | Z9: =S9*(1+'Pricing Policies'!$C$7/100)*'Pricing Policies'!$D$4*IF($C9="TRF",1,(1+Markups!$B$4/100)) -> 701.84415 | AA9: =S9*(1+'Pricing Policies'!$C$7/100)*'Pricing Policies'!$E$4*IF($C9="TRF",1,(1+Markups!$B$4/100)) -> 825.699 | AB9: =S9*(1+'Pricing Policies'!$C$7/100)*'Pricing Policies'!$F$4*IF($C9="TRF",1,(1+Markups!$B$4/100)) -> 990.8388 | AC9: =AC$2 -> 2 | AD9: =AC9*K9 -> 0 | AE9: =AD9*(1+'Pricing Policies'!$C$12/100)*'Pricing Policies'!$D$11 -> 0 | AF9: =AD9*(1+'Pricing Policies'!$C$12/100)*'Pricing Policies'!$E$11 -> 0 | AG9: =AD9*(1+'Pricing Policies'!$C$12/100)*'Pricing Policies'!$F$11 -> 0 | AH9: =AD9*(1+'Pricing Policies'!$C$13/100)*'Pricing Policies'!$D$11 -> 0 | AI9: =AD9*(1+'Pricing Policies'!$C$13/100)*'Pricing Policies'!$E$11 -> 0 | AJ9: =AD9*(1+'Pricing Policies'!$C$13/100)*'Pricing Policies'!$F$11 -> 0 | AK9: =AD9*(1+'Pricing Policies'!$C$14/100)*'Pricing Policies'!$D$11 -> 0 | AL9: =AD9*(1+'Pricing Policies'!$C$14/100)*'Pricing Policies'!$E$11 -> 0 | AM9: =AD9*(1+'Pricing Policies'!$C$14/100)*'Pricing Policies'!$F$11 -> 0 | AN9: =(T$2*T9+U$2*U9+V$2*V9+W$2*W9+X$2*X9+Y$2*Y9+Z$2*Z9+AA$2*AA9+AB$2*AB9) -> 708.48621 | AO9: =(AE$2*AE9+AF$2*AF9+AG$2*AG9+AH$2*AH9+AI$2*AI9+AJ$2*AJ9+AK$2*AK9+AL$2*AL9+AM$2*AM9) -> 0 | AP9: =AN9+AO9 -> 708.48621 | AQ9: =CEILING(AP9,5) -> 710 | AR9: =AR$2 -> 0.1 | AS9: =AQ9*AR9 -> 71 | AT9: =AT$2 -> 0.05 | AU9: =(AQ9+AS9)*AT9 -> 39.05 | AV9: =AQ9+AS9+AU9 -> 820.05 | AW9: =CEILING(AV9,5) -> 825 | AX9: =AW9-AU9-AS9-AD9 -> 714.95 | AY9: =AX9*AY$2 -> 178.7375 | AZ9: =AY9/D9 -> 17.87375 | BA9: =IF(AZ9<BD$9,BD$9,IF(AZ9>BD$10,BD$10,AZ9)) -> 17.87375 | BC9: Costo minimo garantito | BD9: 15
A10: =CONCATENATE(B10, " - ",C10) -> Suvereto - TOUR FD+ | B10: Suvereto | C10: TOUR FD+ | D10: 10 | E10: 400 | F10: 0 | M10: =(E10)*'Base Operating Costs'!$B$13 -> 76 | N10: =(E10)*'Base Operating Costs'!$B$14 -> 56.286885 | O10: ='Base Operating Costs'!$B$15*(E10) -> 64.40075 | P10: =D10*'Base Operating Costs'!$B$4 -> 220 | Q10: =F10 -> 0 | R10: =M10+N10+O10+P10+Q10 -> 416.68764 | S10: =R10*((100+O$2*EXP(-1*E10/P$2))/100)*IF(E10<M$2,1,(1-(N$2/100))) -> 416.7566 | T10: =S10*(1+'Pricing Policies'!$C$5/100)*'Pricing Policies'!$D$4*IF($C10="TRF",1,(1+Markups!$B$4/100)) -> 602.21328 | U10: =S10*(1+'Pricing Policies'!$C$5/100)*'Pricing Policies'!$E$4*IF($C10="TRF",1,(1+Markups!$B$4/100)) -> 708.48621 | V10: =S10*(1+'Pricing Policies'!$C$5/100)*'Pricing Policies'!$F$4*IF($C10="TRF",1,(1+Markups!$B$4/100)) -> 850.18345 | W10: =S10*(1+'Pricing Policies'!$C$6/100)*'Pricing Policies'!$D$4*IF($C10="TRF",1,(1+Markups!$B$4/100)) -> 642.06563 | X10: =S10*(1+'Pricing Policies'!$C$6/100)*'Pricing Policies'!$E$4*IF($C10="TRF",1,(1+Markups!$B$4/100)) -> 755.37133 | Y10: =S10*(1+'Pricing Policies'!$C$6/100)*'Pricing Policies'!$F$4*IF($C10="TRF",1,(1+Markups!$B$4/100)) -> 906.44559 | Z10: =S10*(1+'Pricing Policies'!$C$7/100)*'Pricing Policies'!$D$4*IF($C10="TRF",1,(1+Markups!$B$4/100)) -> 701.84415 | AA10: =S10*(1+'Pricing Policies'!$C$7/100)*'Pricing Policies'!$E$4*IF($C10="TRF",1,(1+Markups!$B$4/100)) -> 825.699 | AB10: =S10*(1+'Pricing Policies'!$C$7/100)*'Pricing Policies'!$F$4*IF($C10="TRF",1,(1+Markups!$B$4/100)) -> 990.8388 | AC10: =AC$2 -> 2 | AD10: =AC10*K10 -> 0 | AE10: =AD10*(1+'Pricing Policies'!$C$12/100)*'Pricing Policies'!$D$11 -> 0 | AF10: =AD10*(1+'Pricing Policies'!$C$12/100)*'Pricing Policies'!$E$11 -> 0 | AG10: =AD10*(1+'Pricing Policies'!$C$12/100)*'Pricing Policies'!$F$11 -> 0 | AH10: =AD10*(1+'Pricing Policies'!$C$13/100)*'Pricing Policies'!$D$11 -> 0 | AI10: =AD10*(1+'Pricing Policies'!$C$13/100)*'Pricing Policies'!$E$11 -> 0 | AJ10: =AD10*(1+'Pricing Policies'!$C$13/100)*'Pricing Policies'!$F$11 -> 0 | AK10: =AD10*(1+'Pricing Policies'!$C$14/100)*'Pricing Policies'!$D$11 -> 0 | AL10: =AD10*(1+'Pricing Policies'!$C$14/100)*'Pricing Policies'!$E$11 -> 0 | AM10: =AD10*(1+'Pricing Policies'!$C$14/100)*'Pricing Policies'!$F$11 -> 0 | AN10: =(T$2*T10+U$2*U10+V$2*V10+W$2*W10+X$2*X10+Y$2*Y10+Z$2*Z10+AA$2*AA10+AB$2*AB10) -> 708.48621 | AO10: =(AE$2*AE10+AF$2*AF10+AG$2*AG10+AH$2*AH10+AI$2*AI10+AJ$2*AJ10+AK$2*AK10+AL$2*AL10+AM$2*AM10) -> 0 | AP10: =AN10+AO10 -> 708.48621 | AQ10: =CEILING(AP10,5) -> 710 | AR10: =AR$2 -> 0.1 | AS10: =AQ10*AR10 -> 71 | AT10: =AT$2 -> 0.05 | AU10: =(AQ10+AS10)*AT10 -> 39.05 | AV10: =AQ10+AS10+AU10 -> 820.05 | AW10: =CEILING(AV10,5) -> 825 | AX10: =AW10-AU10-AS10-AD10 -> 714.95 | AY10: =AX10*AY$2 -> 178.7375 | AZ10: =AY10/D10 -> 17.87375 | BA10: =IF(AZ10<BD$9,BD$9,IF(AZ10>BD$10,BD$10,AZ10)) -> 17.87375 | BC10: Costo massimo riconosciuto | BD10: 22
